File: Pole Figure Data/111.txt
[Measurement conditions]
Sample identification
Comment
Anode material	Cu
K-Alpha1 wavelength	1.540598
K-Alpha2 wavelength	1.544426
Ratio K-Alpha2/K-Alpha1	0.5
Divergence slit	Fixed	1.00mm
Receiving slit	1
Monochromator used	YES
Generator voltage	45
Tube current	40
File date and time	7/7/2006 19:37
Unit cell
h k l	 1 1 1
No. of scans	18
Psi range	0	85	5
Phi range	0	360	5
No. of points per scan	72
Scan type	CONTINUOUS
2Theta	38.891
Omega	19.4455
X	-12
Y	12
Z	2.45
Time per step	1
115	142	143	176	318	499	834	1159	937	512	282	193	141	130	117	83	68	31
125	125	126	182	261	488	900	1186	1017	550	331	232	153	136	123	103	86	33
113	122	150	172	235	465	773	1152	1029	643	404	220	197	168	140	126	73	27
112	124	140	174	265	411	657	1029	980	735	432	283	220	179	159	138	89	38
107	113	135	152	229	359	598	850	977	736	476	313	282	206	180	168	118	53
118	112	106	163	196	321	491	756	877	726	534	383	304	220	176	125	97	48
110	138	133	168	189	306	428	663	793	734	554	399	347	286	187	107	68	38
107	126	98	148	187	277	415	623	762	757	575	409	296	226	179	103	48	29
105	122	118	158	219	254	381	540	816	830	635	380	271	191	130	96	38	18
103	119	142	138	190	255	401	587	877	960	700	411	202	154	128	78	42	16
121	104	123	151	204	259	391	606	900	1088	868	529	258	174	135	112	39	14
115	106	123	151	203	248	401	616	929	1035	840	564	381	230	164	106	63	11
113	96	125	150	182	268	398	652	916	932	750	501	360	292	210	148	78	35
138	123	128	160	187	284	409	648	880	870	635	386	287	249	196	123	56	26
119	107	121	157	153	299	446	725	933	810	552	425	265	178	145	83	54	24
111	146	143	137	224	312	468	712	922	802	541	340	260	186	138	87	61	28
129	118	123	157	192	285	454	774	976	873	537	346	264	185	156	113	89	36
118	113	153	170	201	293	476	744	1043	814	606	402	272	168	158	133	72	35
125	116	137	169	216	304	491	785	986	873	542	401	246	230	164	124	96	33
138	124	148	181	213	351	534	823	1005	860	592	352	251	203	165	153	98	32
149	130	121	166	229	331	497	872	1048	891	595	329	199	165	157	117	61	22
130	134	134	168	212	320	511	863	1054	898	563	344	218	133	133	73	43	19
119	115	125	194	223	355	609	904	1109	911	606	340	231	166	112	69	48	28
140	134	147	165	249	365	576	822	999	858	605	378	239	175	122	65	53	26
105	100	144	178	247	398	587	772	855	776	538	386	247	197	126	116	56	31
109	141	135	167	242	413	595	732	789	713	481	302	227	166	160	124	89	31
133	121	139	182	250	385	626	731	712	573	451	284	240	147	138	105	80	33
130	101	167	199	279	435	602	712	706	601	400	258	202	145	120	93	64	28
119	129	139	189	322	467	659	780	784	621	398	267	183	139	105	81	45	29
129	138	126	238	314	526	759	954	958	708	516	347	257	180	127	83	60	23
133	130	160	214	363	575	863	1093	1042	773	514	341	269	217	130	89	55	19
109	124	177	232	414	578	1026	1212	1079	695	520	363	269	233	154	98	42	20
134	120	195	221	421	720	1078	1306	1084	665	465	351	340	265	228	118	55	19
111	126	180	277	438	783	1115	1277	959	651	483	373	383	323	295	204	79	37
128	137	154	268	508	771	1196	1198	857	527	411	349	324	335	300	232	107	33
117	150	206	280	481	826	1175	1146	735	470	338	290	263	243	223	202	108	31
131	167	214	273	511	819	1207	999	650	411	264	249	164	174	176	129	112	52
142	137	189	281	520	794	1085	918	548	320	227	154	144	121	121	111	67	28
103	116	209	306	497	823	928	850	514	282	203	148	101	108	85	76	46	32
97	140	178	292	491	757	959	843	502	312	201	128	89	92	84	82	58	27
122	139	190	288	471	715	844	760	507	313	217	142	102	110	82	92	63	41
107	156	178	295	457	683	853	793	602	391	253	236	176	150	135	110	61	30
116	131	179	265	441	682	793	833	730	569	399	302	242	206	159	137	96	50
111	135	196	268	428	689	862	867	855	708	566	428	325	292	194	131	62	36
118	135	161	265	414	665	821	915	838	780	633	525	358	259	189	104	52	30
134	131	165	287	445	667	826	853	858	674	560	407	322	287	170	124	38	24
109	144	179	245	413	655	841	842	749	576	446	331	311	311	217	114	48	19
129	139	188	252	441	673	827	760	687	502	438	376	454	422	267	141	63	22
107	131	178	280	458	636	808	717	620	491	498	489	475	485	310	135	79	19
141	131	187	325	442	629	773	687	615	540	523	563	619	582	412	183	67	27
121	134	173	273	443	623	771	746	595	560	485	524	562	606	425	219	89	14
124	137	195	259	441	661	680	716	546	531	472	493	528	540	447	260	133	49
122	150	179	313	426	575	738	692	583	484	439	421	481	466	392	246	121	41
135	151	194	300	396	558	693	682	543	465	419	395	376	336	284	162	80	26
106	136	193	258	440	529	671	669	600	562	413	381	336	258	218	120	67	30
130	140	209	264	377	502	651	637	614	484	397	279	240	197	142	112	59	23
125	143	188	262	365	538	656	694	586	484	303	217	158	118	92	70	27	18
118	143	167	244	359	502	667	617	577	348	243	173	136	99	104	79	32	19
115	127	157	252	364	435	574	663	557	345	244	175	171	209	158	119	79	25
123	139	167	224	319	405	558	629	494	381	271	235	232	260	342	215	130	44
129	170	168	188	248	421	517	579	514	422	307	233	302	315	319	233	116	24
113	135	155	187	318	436	524	604	617	509	421	337	308	297	223	161	104	33
112	132	155	222	315	433	550	659	663	581	569	448	403	317	229	147	83	33
123	111	149	209	295	490	619	713	784	684	628	524	517	405	281	161	75	28
128	125	143	230	300	457	662	860	848	716	638	524	436	356	262	158	92	23
130	138	148	240	313	501	797	1004	1012	857	634	477	385	287	208	142	58	22
132	141	158	220	324	521	835	1141	1132	900	624	486	361	263	202	127	71	25
136	126	159	222	342	495	816	1127	1111	918	624	461	341	266	205	115	57	18
126	145	176	223	316	521	768	995	992	681	500	347	272	231	193	114	81	28
139	131	150	224	283	545	783	922	825	539	351	238	184	167	145	102	82	40
125	131	173	196	320	493	802	940	733	449	275	163	153	147	123	102	64	30
116	123	139	185	293	494	832	1006	824	451	265	173	157	128	119	98	58	30